<?xml version="1.0" encoding="utf-8"?>
<!-- This URDF was automatically created by SolidWorks to URDF Exporter! Originally created by Stephen Brawner (brawner@gmail.com) 
     Commit Version: 1.6.0-4-g7f85cfe  Build Version: 1.6.7995.38578
     For more information, please see http://wiki.ros.org/sw_urdf_exporter -->
<robot
  name="XM7p">
  <link
    name="base_link">
    <inertial>
      <origin
        xyz="-0.019095 3.5865E-05 0.074179"
        rpy="0 0 0" />
      <mass
        value="7.756" />
      <inertia
        ixx="0.04077"
        ixy="3.0813E-05"
        ixz="-0.0058221"
        iyy="0.052589"
        iyz="6.6559E-06"
        izz="0.044751" />
    </inertial>
    <visual>
      <origin
        xyz="0 0 0"
        rpy="0 0 0" />
      <geometry>
        <mesh
          filename="package://XM7p/meshes/base_link.STL" />
      </geometry>
      <material
        name="">
        <color
          rgba="1 1 1 1" />
      </material>
    </visual>
    <collision>
      <origin
        xyz="0 0 0"
        rpy="0 0 0" />
      <geometry>
        <mesh
          filename="package://XM7p/meshes/base_link.STL" />
      </geometry>
    </collision>
  </link>
  <link
    name="link1">
    <inertial>
      <origin
        xyz="5.8834E-06 -0.030793 -0.066288"
        rpy="0 0 0" />
      <mass
        value="5.4372" />
      <inertia
        ixx="0.043824"
        ixy="-2.0753E-06"
        ixz="-5.7908E-06"
        iyy="0.039523"
        iyz="0.0085155"
        izz="0.015768" />
    </inertial>
    <visual>
      <origin
        xyz="0 0 0"
        rpy="0 0 0" />
      <geometry>
        <mesh
          filename="package://XM7p/meshes/link1.STL" />
      </geometry>
      <material
        name="">
        <color
          rgba="1 1 1 1" />
      </material>
    </visual>
    <collision>
      <origin
        xyz="0 0 0"
        rpy="0 0 0" />
      <geometry>
        <mesh
          filename="package://XM7p/meshes/link1.STL" />
      </geometry>
    </collision>
  </link>
  <joint
    name="joint1"
    type="revolute">
    <origin
      xyz="0 0 0.404"
      rpy="0 0 0" />
    <parent
      link="base_link" />
    <child
      link="link1" />
    <axis
      xyz="0 0 1" />
    <limit
      lower="-2.97"
      upper="2.97"
      effort="85"
      velocity="2.175" />
  </joint>
  <link
    name="link2">
    <inertial>
      <origin
        xyz="-4.795E-06 0.097106 0.038346"
        rpy="0 0 0" />
      <mass
        value="4.6815" />
      <inertia
        ixx="0.055152"
        ixy="3.2348E-06"
        ixz="-9.7274E-07"
        iyy="0.012283"
        iyz="0.01393"
        izz="0.051008" />
    </inertial>
    <visual>
      <origin
        xyz="0 0 0"
        rpy="0 0 0" />
      <geometry>
        <mesh
          filename="package://XM7p/meshes/link2.STL" />
      </geometry>
      <material
        name="">
        <color
          rgba="1 1 1 1" />
      </material>
    </visual>
    <collision>
      <origin
        xyz="0 0 0"
        rpy="0 0 0" />
      <geometry>
        <mesh
          filename="package://XM7p/meshes/link2.STL" />
      </geometry>
    </collision>
  </link>
  <joint
    name="joint2"
    type="revolute">
    <origin
      xyz="0 0 0"
      rpy="1.5708 0 3.1416" />
    <parent
      link="link1" />
    <child
      link="link2" />
    <axis
      xyz="0 0 1" />
    <limit
      lower="-2.09"
      upper="2.09"
      effort="85"
      velocity="2.175" />
  </joint>
  <link
    name="link3">
    <inertial>
      <origin
        xyz="9.2637E-07 -0.025672 -0.051737"
        rpy="0 0 0" />
      <mass
        value="2.6054" />
      <inertia
        ixx="0.013546"
        ixy="-9.8457E-07"
        ixz="-7.0341E-07"
        iyy="0.012094"
        iyz="0.0027648"
        izz="0.0048088" />
    </inertial>
    <visual>
      <origin
        xyz="0 0 0"
        rpy="0 0 0" />
      <geometry>
        <mesh
          filename="package://XM7p/meshes/link3.STL" />
      </geometry>
      <material
        name="">
        <color
          rgba="1 1 1 1" />
      </material>
    </visual>
    <collision>
      <origin
        xyz="0 0 0"
        rpy="0 0 0" />
      <geometry>
        <mesh
          filename="package://XM7p/meshes/link3.STL" />
      </geometry>
    </collision>
  </link>
  <joint
    name="joint3"
    type="revolute">
    <origin
      xyz="0 0.4375 0"
      rpy="1.5708 0 3.1416" />
    <parent
      link="link2" />
    <child
      link="link3" />
    <axis
      xyz="0 0 1" />
    <limit
      lower="-2.97"
      upper="2.97"
      effort="85"
      velocity="2.175" />
  </joint>
  <link
    name="link4">
    <inertial>
      <origin
        xyz="-3.0864E-06 0.075674 0.032909"
        rpy="0 0 0" />
      <mass
        value="2.6465" />
      <inertia
        ixx="0.019258"
        ixy="1.1423E-06"
        ixz="-3.5897E-07"
        iyy="0.0049485"
        iyz="0.0051123"
        izz="0.017278" />
    </inertial>
    <visual>
      <origin
        xyz="0 0 0"
        rpy="0 0 0" />
      <geometry>
        <mesh
          filename="package://XM7p/meshes/link4.STL" />
      </geometry>
      <material
        name="">
        <color
          rgba="1 1 1 1" />
      </material>
    </visual>
    <collision>
      <origin
        xyz="0 0 0"
        rpy="0 0 0" />
      <geometry>
        <mesh
          filename="package://XM7p/meshes/link4.STL" />
      </geometry>
    </collision>
  </link>
  <joint
    name="joint4"
    type="revolute">
    <origin
      xyz="0 0 0"
      rpy="1.5708 0 3.1416" />
    <parent
      link="link3" />
    <child
      link="link4" />
    <axis
      xyz="0 0 1" />
    <limit
      lower="-2.09"
      upper="2.09"
      effort="85"
      velocity="2.175" />
  </joint>
  <link
    name="link5">
    <inertial>
      <origin
        xyz="9.6604E-06 -0.023095 -0.066588"
        rpy="0 0 0" />
      <mass
        value="2.5198" />
      <inertia
        ixx="0.016116"
        ixy="-9.4059E-07"
        ixz="1.3785E-06"
        iyy="0.014054"
        iyz="0.0031845"
        izz="0.0043812" />
    </inertial>
    <visual>
      <origin
        xyz="0 0 0"
        rpy="0 0 0" />
      <geometry>
        <mesh
          filename="package://XM7p/meshes/link5.STL" />
      </geometry>
      <material
        name="">
        <color
          rgba="1 1 1 1" />
      </material>
    </visual>
    <collision>
      <origin
        xyz="0 0 0"
        rpy="0 0 0" />
      <geometry>
        <mesh
          filename="package://XM7p/meshes/link5.STL" />
      </geometry>
    </collision>
  </link>
  <joint
    name="joint5"
    type="revolute">
    <origin
      xyz="0 0.4125 0"
      rpy="1.5708 0 3.1416" />
    <parent
      link="link4" />
    <child
      link="link5" />
    <axis
      xyz="0 0 1" />
    <limit
      lower="-2.97"
      upper="2.97"
      effort="36"
      velocity="2.61" />
  </joint>
  <link
    name="link6">
    <inertial>
      <origin
        xyz="-1.8004E-05 0.094771 0.01896"
        rpy="0 0 0" />
      <mass
        value="1.9096" />
      <inertia
        ixx="0.011346"
        ixy="-1.3488E-06"
        ixz="5.0282E-07"
        iyy="0.0026838"
        iyz="0.0027856"
        izz="0.010421" />
    </inertial>
    <visual>
      <origin
        xyz="0 0 0"
        rpy="0 0 0" />
      <geometry>
        <mesh
          filename="package://XM7p/meshes/link6.STL" />
      </geometry>
      <material
        name="">
        <color
          rgba="1 1 1 1" />
      </material>
    </visual>
    <collision>
      <origin
        xyz="0 0 0"
        rpy="0 0 0" />
      <geometry>
        <mesh
          filename="package://XM7p/meshes/link6.STL" />
      </geometry>
    </collision>
  </link>
  <joint
    name="joint6"
    type="revolute">
    <origin
      xyz="0 0 0"
      rpy="1.5708 0 3.1416" />
    <parent
      link="link5" />
    <child
      link="link6" />
    <axis
      xyz="0 0 1" />
    <limit
      lower="-2.09"
      upper="2.09"
      effort="36"
      velocity="2.61" />
  </joint>
  <link
    name="link7">
    <inertial>
      <origin
        xyz="3.9288E-05 0.020938 -0.046793"
        rpy="0 0 0" />
      <mass
        value="0.87838" />
      <inertia
        ixx="0.0018386"
        ixy="-4.1625E-07"
        ixz="-6.6741E-07"
        iyy="0.0010239"
        iyz="0.00037753"
        izz="0.0015317" />
    </inertial>
    <visual>
      <origin
        xyz="0 0 0"
        rpy="0 0 0" />
      <geometry>
        <mesh
          filename="package://XM7p/meshes/link7.STL" />
      </geometry>
      <material
        name="">
        <color
          rgba="1 1 1 1" />
      </material>
    </visual>
    <collision>
      <origin
        xyz="0 0 0"
        rpy="0 0 0" />
      <geometry>
        <mesh
          filename="package://XM7p/meshes/link7.STL" />
      </geometry>
    </collision>
  </link>
  <joint
    name="joint7"
    type="revolute">
    <origin
      xyz="0 0.2755 0"
      rpy="1.5708 0 3.1416" />
    <parent
      link="link6" />
    <child
      link="link7" />
    <axis
      xyz="0 0 1" />
    <limit
      lower="-6.28"
      upper="6.28"
      effort="36"
      velocity="2.61" />
  </joint>
</robot>